[2021-11-06 16:49:08,161: INFO/MainProcess] Connected to redis://redis:6379/0
[2021-11-06 16:49:08,363: INFO/MainProcess] mingle: searching for neighbors
[2021-11-06 16:49:10,045: INFO/MainProcess] mingle: all alone
[2021-11-06 16:49:10,110: INFO/MainProcess] celery@8cefbf66c157 ready.
[2021-11-06 16:49:13,518: INFO/MainProcess] Events of group {task} enabled by remote.
[2021-11-06 16:55:48,694: INFO/MainProcess] Connected to redis://redis:6379/0
[2021-11-06 16:55:48,716: INFO/MainProcess] mingle: searching for neighbors
[2021-11-06 16:55:49,748: INFO/MainProcess] mingle: all alone
[2021-11-06 16:55:49,764: INFO/MainProcess] celery@bd2a2595bd14 ready.
[2021-11-06 16:55:50,141: INFO/MainProcess] Events of group {task} enabled by remote.
[2021-11-06 17:02:59,422: INFO/MainProcess] Connected to redis://redis:6379/0
[2021-11-06 17:02:59,437: INFO/MainProcess] mingle: searching for neighbors
[2021-11-06 17:03:00,460: INFO/MainProcess] mingle: all alone
[2021-11-06 17:03:00,476: INFO/MainProcess] celery@bd2a2595bd14 ready.
[2021-11-06 17:03:01,613: INFO/MainProcess] Events of group {task} enabled by remote.
[2021-11-06 17:04:13,127: INFO/MainProcess] Received task: file_conversion[12796ffd-a222-4b71-adb4-8e9c206a7cbc]  
[2021-11-06 17:04:20,445: WARNING/ForkPoolWorker-15] DONE
[2021-11-06 17:04:20,987: INFO/ForkPoolWorker-15] Task file_conversion[12796ffd-a222-4b71-adb4-8e9c206a7cbc] succeeded in 7.841742008999972s: True
[2021-11-06 17:07:39,685: WARNING/MainProcess] consumer: Connection to broker lost. Trying to re-establish the connection...
Traceback (most recent call last):
  File "/usr/local/lib/python3.9/site-packages/celery/worker/consumer/consumer.py", line 318, in start
    blueprint.start(self)
  File "/usr/local/lib/python3.9/site-packages/celery/bootsteps.py", line 119, in start
    step.start(parent)
  File "/usr/local/lib/python3.9/site-packages/celery/worker/consumer/consumer.py", line 599, in start
    c.loop(*c.loop_args())
  File "/usr/local/lib/python3.9/site-packages/celery/worker/loops.py", line 83, in asynloop
    next(loop)
  File "/usr/local/lib/python3.9/site-packages/kombu/asynchronous/hub.py", line 364, in create_loop
    cb(*cbargs)
  File "/usr/local/lib/python3.9/site-packages/kombu/transport/redis.py", line 1083, in on_readable
    self.cycle.on_readable(fileno)
  File "/usr/local/lib/python3.9/site-packages/kombu/transport/redis.py", line 354, in on_readable
    chan.handlers[type]()
  File "/usr/local/lib/python3.9/site-packages/kombu/transport/redis.py", line 688, in _receive
    ret.append(self._receive_one(c))
  File "/usr/local/lib/python3.9/site-packages/kombu/transport/redis.py", line 698, in _receive_one
    response = c.parse_response()
  File "/usr/local/lib/python3.9/site-packages/redis/client.py", line 3505, in parse_response
    response = self._execute(conn, conn.read_response)
  File "/usr/local/lib/python3.9/site-packages/redis/client.py", line 3479, in _execute
    return command(*args, **kwargs)
  File "/usr/local/lib/python3.9/site-packages/redis/connection.py", line 739, in read_response
    response = self._parser.read_response()
  File "/usr/local/lib/python3.9/site-packages/redis/connection.py", line 324, in read_response
    raw = self._buffer.readline()
  File "/usr/local/lib/python3.9/site-packages/redis/connection.py", line 256, in readline
    self._read_from_socket()
  File "/usr/local/lib/python3.9/site-packages/redis/connection.py", line 201, in _read_from_socket
    raise ConnectionError(SERVER_CLOSED_CONNECTION_ERROR)
redis.exceptions.ConnectionError: Connection closed by server.
[2021-11-06 17:07:39,733: ERROR/MainProcess] consumer: Cannot connect to redis://redis:6379/0: Error 111 connecting to redis:6379. Connection refused..
Trying again in 2.00 seconds... (1/100)

